Workbook

Sheet HiringCafe_Database
A1: Posted Time | B1: Role | C1: Area | D1: Work Type | E1: Contract Type | F1: Company | G1: Company & Description | H1: Requirements Summary | I1: Technical Tools mentioned | J1: Job Posting | K1: Added Date | L1: Type of Search | M1: Posted Date (DATE format)
A2: 12h | B2: Insight Analyst - Customer Success | C2: Budapest, Budapest, Hungary | D2: Hybrid | E2: Full Time | F2: NielsenIQ | G2: NielsenIQNYSE: NIQ: Provides data and analytics on global consumer buying behavior. | H2: 1+ YOE1-3 years of data analysis experience; English fluency; ability to collaborate with clients; knowledge of data delivery and reporting. | I2: Not available | J2: Job Posting | K2: 46083 | L2: Departments - Data and Analytics, Budapest (Remote, Hybrid, Onsite), No keyword search, 6 months | M2: =IFERROR(__xludf.DUMMYFUNCTION("TEXT( IF(RIGHT(A2,2)=""mo"", EDATE(DATEVALUE(K2), -VALUE(REGEXEXTRACT(A2,""\d+""))), DATEVALUE(K2) - IF(RIGHT(A2,1)=""h"", VALUE(REGEXEXTRACT(A2,""\d+""))/24, IF(RIGHT(A2,1)=""d"", VALUE(REGEXEXTRACT(A2,""\d+"")), IF(RIGHT(A2,1"&")=""w"", VALUE(REGEXEXTRACT(A2,""\d+""))*7, 0))) ) , ""YYYY-M-D"")"),"2026-3-1") -> 2026-3-1
A3: 1d | B3: Senior SEO/GEO Consultant | C3: Budapest, Budapest, Hungary | D3: Hybrid | E3: Full Time | F3: DEPT | G3: DEPT: Global digital agency providing integrated technology and marketing services. | H3: 5+ YOE5+ years in SEO; fluent English; strategic, analytical thinker; strong communication; able to work independently in a hybrid setting. | I3: Not available | J3: Job Posting | K3: 46083 | L3: Departments - Data and Analytics, Budapest (Remote, Hybrid, Onsite), No keyword search, 6 months | M3: =IFERROR(__xludf.DUMMYFUNCTION("TEXT( IF(RIGHT(A3,2)=""mo"", EDATE(DATEVALUE(K3), -VALUE(REGEXEXTRACT(A3,""\d+""))), DATEVALUE(K3) - IF(RIGHT(A3,1)=""h"", VALUE(REGEXEXTRACT(A3,""\d+""))/24, IF(RIGHT(A3,1)=""d"", VALUE(REGEXEXTRACT(A3,""\d+"")), IF(RIGHT(A3,1"&")=""w"", VALUE(REGEXEXTRACT(A3,""\d+""))*7, 0))) ) , ""YYYY-M-D"")"),"2026-3-1") -> 2026-3-1
A4: 2d | B4: Global Master Data Administrator Intern (Budapest, HU, H-1138) | C4: Budapest, Budapest, Hungary | D4: Hybrid | E4: All Commitments Available | F4: Givaudan | G4: GivaudanSIX Swiss Exchange: GIVN: Global manufacturer of flavors, fragrances, and active cosmetic ingredients. | H4: Pursuing university degree (IT or Business); fluent English; intermediate Excel; SAP experience beneficial. | I4: Microsoft Excel, SAP | J4: Job Posting | K4: 46083 | L4: Departments - Data and Analytics, Budapest (Remote, Hybrid, Onsite), No keyword search, 6 months | M4: =IFERROR(__xludf.DUMMYFUNCTION("TEXT( IF(RIGHT(A4,2)=""mo"", EDATE(DATEVALUE(K4), -VALUE(REGEXEXTRACT(A4,""\d+""))), DATEVALUE(K4) - IF(RIGHT(A4,1)=""h"", VALUE(REGEXEXTRACT(A4,""\d+""))/24, IF(RIGHT(A4,1)=""d"", VALUE(REGEXEXTRACT(A4,""\d+"")), IF(RIGHT(A4,1"&")=""w"", VALUE(REGEXEXTRACT(A4,""\d+""))*7, 0))) ) , ""YYYY-M-D"")"),"2026-2-28") -> 2026-2-28
A5: 2d | B5: Head of Experimentations | C5: Ukraine or Turkey or Serbia or Georgia or Moldova or Montenegro or Macedonia or Kazakhstan or Europe | D5: Remote | E5: Full Time | F5: Ruby Labs | G5: Ruby Labs: Creates and operates innovative consumer mobile products globally. | H5: 7+ YOESenior growth leader with 7+ years in growth, CRO, product growth, or performance strategy; proven success scaling digital subscription products; strong analytics and experimentation expertise; English proficiency. | I5: A/B testing platforms, Analytics platforms | J5: Job Posting | K5: 46083 | L5: Departments - Data and Analytics, Budapest (Remote, Hybrid, Onsite), No keyword search, 6 months | M5: =IFERROR(__xludf.DUMMYFUNCTION("TEXT( IF(RIGHT(A5,2)=""mo"", EDATE(DATEVALUE(K5), -VALUE(REGEXEXTRACT(A5,""\d+""))), DATEVALUE(K5) - IF(RIGHT(A5,1)=""h"", VALUE(REGEXEXTRACT(A5,""\d+""))/24, IF(RIGHT(A5,1)=""d"", VALUE(REGEXEXTRACT(A5,""\d+"")), IF(RIGHT(A5,1"&")=""w"", VALUE(REGEXEXTRACT(A5,""\d+""))*7, 0))) ) , ""YYYY-M-D"")"),"2026-2-28") -> 2026-2-28
A6: 3d | B6: Quantitative Researcher | C6: Budapest, Budapest, Hungary | D6: Onsite | E6: Full Time | F6: MSCI | G6: MSCINYSE: MSCI: Provides investment indices, data, and portfolio risk analytics. | H6: Advanced degree (Masters or PhD) in a quantitative field; strong quantitative and problem-solving skills; ability to communicate with senior stakeholders; interest in empirical modeling and data science; Proficiency in Python, MATLAB, and production C++. | I6: Python, MATLAB, C++ | J6: Job Posting | K6: 46083 | L6: Departments - Data and Analytics, Budapest (Remote, Hybrid, Onsite), No keyword search, 6 months | M6: =IFERROR(__xludf.DUMMYFUNCTION("TEXT( IF(RIGHT(A6,2)=""mo"", EDATE(DATEVALUE(K6), -VALUE(REGEXEXTRACT(A6,""\d+""))), DATEVALUE(K6) - IF(RIGHT(A6,1)=""h"", VALUE(REGEXEXTRACT(A6,""\d+""))/24, IF(RIGHT(A6,1)=""d"", VALUE(REGEXEXTRACT(A6,""\d+"")), IF(RIGHT(A6,1"&")=""w"", VALUE(REGEXEXTRACT(A6,""\d+""))*7, 0))) ) , ""YYYY-M-D"")"),"2026-2-27") -> 2026-2-27
A7: 3d | B7: Digitalization Specialist, Reporting CoE (Budapest, PE, HU, 1062) | C7: Budapest, Budapest, Hungary | D7: Hybrid | E7: Full Time | F7: Grundfos | G7: Grundfos: Global manufacturer of energy-efficient water pumps and systems. | H7: 3+ YOEBachelor’s or Master’s in Finance, Economics, Business, Data/Analytics; 3–5 years in finance processes; hands-on with Power BI, Power Automate, Power Apps; familiarity with Copilot Studio and agentic AI workflows. | I7: Power BI, Power Automate, Power Apps, Microsoft Copilot Studio, Agentic AI workflows | J7: Job Posting | K7: 46083 | L7: Departments - Data and Analytics, Budapest (Remote, Hybrid, Onsite), No keyword search, 6 months | M7: =IFERROR(__xludf.DUMMYFUNCTION("TEXT( IF(RIGHT(A7,2)=""mo"", EDATE(DATEVALUE(K7), -VALUE(REGEXEXTRACT(A7,""\d+""))), DATEVALUE(K7) - IF(RIGHT(A7,1)=""h"", VALUE(REGEXEXTRACT(A7,""\d+""))/24, IF(RIGHT(A7,1)=""d"", VALUE(REGEXEXTRACT(A7,""\d+"")), IF(RIGHT(A7,1"&")=""w"", VALUE(REGEXEXTRACT(A7,""\d+""))*7, 0))) ) , ""YYYY-M-D"")"),"2026-2-27") -> 2026-2-27
A8: 3d | B8: Data analyst (Budapest, BU, HU, 1068) | C8: Budapest, Budapest, Hungary | D8: Onsite | E8: Full Time | F8: Bertelsmann | G8: Bertelsmann: Global media, publishing, and business services conglomerate. | H8: 2+ YOE2-4 years of data analyst or business analyst experience; strong SQL; Python; Power BI; advanced Excel; statistical basics and data modeling; data visualization; stakeholder management. | I8: SQL, Python, Power BI, Excel, Power Pivot, Power Query | J8: Job Posting | K8: 46083 | L8: Departments - Data and Analytics, Budapest (Remote, Hybrid, Onsite), No keyword search, 6 months | M8: =IFERROR(__xludf.DUMMYFUNCTION("TEXT( IF(RIGHT(A8,2)=""mo"", EDATE(DATEVALUE(K8), -VALUE(REGEXEXTRACT(A8,""\d+""))), DATEVALUE(K8) - IF(RIGHT(A8,1)=""h"", VALUE(REGEXEXTRACT(A8,""\d+""))/24, IF(RIGHT(A8,1)=""d"", VALUE(REGEXEXTRACT(A8,""\d+"")), IF(RIGHT(A8,1"&")=""w"", VALUE(REGEXEXTRACT(A8,""\d+""))*7, 0))) ) , ""YYYY-M-D"")"),"2026-2-27") -> 2026-2-27
A9: 4d | B9: Data Platform Developer Trainee | C9: Budapest, Budapest, Hungary | D9: Remote | E9: Internship | F9: Hiflylabs | G9: Hiflylabs: We provide expert data engineering, AI, and analytics solutions. | H9: 0+ YOECurious, eager to learn data engineering, with SQL basics and Python familiarity; active student, at least 1 full semester remaining, 20 hours/week. | I9: SQL, Python, Git | J9: Job Posting | K9: 46083 | L9: Departments - Data and Analytics, Budapest (Remote, Hybrid, Onsite), No keyword search, 6 months | M9: =IFERROR(__xludf.DUMMYFUNCTION("TEXT( IF(RIGHT(A9,2)=""mo"", EDATE(DATEVALUE(K9), -VALUE(REGEXEXTRACT(A9,""\d+""))), DATEVALUE(K9) - IF(RIGHT(A9,1)=""h"", VALUE(REGEXEXTRACT(A9,""\d+""))/24, IF(RIGHT(A9,1)=""d"", VALUE(REGEXEXTRACT(A9,""\d+"")), IF(RIGHT(A9,1"&")=""w"", VALUE(REGEXEXTRACT(A9,""\d+""))*7, 0))) ) , ""YYYY-M-D"")"),"2026-2-26") -> 2026-2-26
A10: 4d | B10: Jr. Master Data Specialist_fixed-term (Budapest, Budapest, HU, 1007) | C10: Budapest, Budapest, Hungary | D10: Onsite | E10: Contract | F10: Reckitt | G10: ReckittLondon Stock Exchange: RKT: Manufacturing and selling consumer hygiene, health, and nutrition products. | H10: 1+ YOEBachelor’s degree in business; at least 1 year data or project management experience; fluent in Hungarian and English; strong Excel skills; experience with integrated finance data handling; good communication and analytical skills; high precision. | I10: Excel, SAP, JDE | J10: Job Posting | K10: 46083 | L10: Departments - Data and Analytics, Budapest (Remote, Hybrid, Onsite), No keyword search, 6 months | M10: =IFERROR(__xludf.DUMMYFUNCTION("TEXT( IF(RIGHT(A10,2)=""mo"", EDATE(DATEVALUE(K10), -VALUE(REGEXEXTRACT(A10,""\d+""))), DATEVALUE(K10) - IF(RIGHT(A10,1)=""h"", VALUE(REGEXEXTRACT(A10,""\d+""))/24, IF(RIGHT(A10,1)=""d"", VALUE(REGEXEXTRACT(A10,""\d+"")), IF(RI"&"GHT(A10,1)=""w"", VALUE(REGEXEXTRACT(A10,""\d+""))*7, 0))) ) , ""YYYY-M-D"")"),"2026-2-26") -> 2026-2-26
A11: 4d | B11: AI Model Validation Expert | C11: Budapest, Budapest, Hungary | D11: Hybrid | E11: Full Time | F11: PwC | G11: PwC: Global provider of audit, tax, and professional consulting services. | H11: 3+ YOE3+ years in developing/validating AI models; degree in quantitative fields; experience in AI/ML, risk, governance; strong communication and leadership; English fluency; German a plus. | I11: Not available | J11: Job Posting | K11: 46083 | L11: Departments - Data and Analytics, Budapest (Remote, Hybrid, Onsite), No keyword search, 6 months | M11: =IFERROR(__xludf.DUMMYFUNCTION("TEXT( IF(RIGHT(A11,2)=""mo"", EDATE(DATEVALUE(K11), -VALUE(REGEXEXTRACT(A11,""\d+""))), DATEVALUE(K11) - IF(RIGHT(A11,1)=""h"", VALUE(REGEXEXTRACT(A11,""\d+""))/24, IF(RIGHT(A11,1)=""d"", VALUE(REGEXEXTRACT(A11,""\d+"")), IF(RI"&"GHT(A11,1)=""w"", VALUE(REGEXEXTRACT(A11,""\d+""))*7, 0))) ) , ""YYYY-M-D"")"),"2026-2-26") -> 2026-2-26
A12: 4d | B12: Marketing Analytics Specialist | C12: Budapest, Budapest, Hungary | D12: Onsite | E12: Full Time | F12: Iron Mountain | G12: Iron MountainNYSE: IRM: Provides enterprise information management, storage, and data center services. | H12: Experience in marketing analytics; strong SQL, BigQuery, Python/R; dashboarding with Tableau/Looker Studio; ability to translate data into business insights. | I12: SQL, BigQuery, Google Cloud Platform, Python, R, JavaScript, GA4, GTM, Tableau, Looker Studio | J12: Job Posting | K12: 46083 | L12: Departments - Data and Analytics, Budapest (Remote, Hybrid, Onsite), No keyword search, 6 months | M12: =IFERROR(__xludf.DUMMYFUNCTION("TEXT( IF(RIGHT(A12,2)=""mo"", EDATE(DATEVALUE(K12), -VALUE(REGEXEXTRACT(A12,""\d+""))), DATEVALUE(K12) - IF(RIGHT(A12,1)=""h"", VALUE(REGEXEXTRACT(A12,""\d+""))/24, IF(RIGHT(A12,1)=""d"", VALUE(REGEXEXTRACT(A12,""\d+"")), IF(RI"&"GHT(A12,1)=""w"", VALUE(REGEXEXTRACT(A12,""\d+""))*7, 0))) ) , ""YYYY-M-D"")"),"2026-2-26") -> 2026-2-26
A13: 4d | B13: Process & Data Analyst | C13: Budapest, Budapest, Hungary | D13: Hybrid | E13: Full Time | F13: bp | G13: bpLondon Stock Exchange: BP: Produces and distributes oil, gas, and renewable energy globally. | H13: BA or master’s in economics or related field; demonstrable data analysis/process improvement experience; strong communication; data integration/ETL; data management; governance familiarity; energy sector knowledge. | I13: SQL, Python, ETL, BPMN, UML, Data Visualization, Data Management, Data Sourcing | J13: Job Posting | K13: 46083 | L13: Departments - Data and Analytics, Budapest (Remote, Hybrid, Onsite), No keyword search, 6 months | M13: =IFERROR(__xludf.DUMMYFUNCTION("TEXT( IF(RIGHT(A13,2)=""mo"", EDATE(DATEVALUE(K13), -VALUE(REGEXEXTRACT(A13,""\d+""))), DATEVALUE(K13) - IF(RIGHT(A13,1)=""h"", VALUE(REGEXEXTRACT(A13,""\d+""))/24, IF(RIGHT(A13,1)=""d"", VALUE(REGEXEXTRACT(A13,""\d+"")), IF(RI"&"GHT(A13,1)=""w"", VALUE(REGEXEXTRACT(A13,""\d+""))*7, 0))) ) , ""YYYY-M-D"")"),"2026-2-26") -> 2026-2-26
A14: 4d | B14: Process & Data Analyst | C14: Budapest, Budapest, Hungary | D14: Hybrid | E14: Full Time | F14: bp | G14: bpLondon Stock Exchange: BP: Global energy providing oil, gas, and low-carbon solutions. | H14: BA or master’s in economics or similar; experience in data analysis or process improvement; strong commercial acumen; proficient in data integration, cleansing, transformation, and visualization; good communication skills; knowledge of data governance and security. | I14: SQL, Python, ETL, Data Visualization, BPMN, UML | J14: Job Posting | K14: 46083 | L14: Departments - Data and Analytics, Budapest (Remote, Hybrid, Onsite), No keyword search, 6 months | M14: =IFERROR(__xludf.DUMMYFUNCTION("TEXT( IF(RIGHT(A14,2)=""mo"", EDATE(DATEVALUE(K14), -VALUE(REGEXEXTRACT(A14,""\d+""))), DATEVALUE(K14) - IF(RIGHT(A14,1)=""h"", VALUE(REGEXEXTRACT(A14,""\d+""))/24, IF(RIGHT(A14,1)=""d"", VALUE(REGEXEXTRACT(A14,""\d+"")), IF(RI"&"GHT(A14,1)=""w"", VALUE(REGEXEXTRACT(A14,""\d+""))*7, 0))) ) , ""YYYY-M-D"")"),"2026-2-26") -> 2026-2-26
A15: 4d | B15: Staff Analytics Product Manager – Operations, Strategy & CTO | C15: Bengaluru or Monterrey or Budapest | D15: Hybrid | E15: Full Time | F15: GE Vernova | G15: GE VernovaNYSE: GEV: Global energy manufacturing power generation and grid technologies. | H15: 7+ YOE7+ years in data management, BI, or analytics; Bachelor’s in STEM; AI/ML experience; BI/tools proficiency. | I15: Power BI, Tableau, Databricks, Azure, AWS, Google Cloud | J15: Job Posting | K15: 46083 | L15: Departments - Data and Analytics, Budapest (Remote, Hybrid, Onsite), No keyword search, 6 months | M15: =IFERROR(__xludf.DUMMYFUNCTION("TEXT( IF(RIGHT(A15,2)=""mo"", EDATE(DATEVALUE(K15), -VALUE(REGEXEXTRACT(A15,""\d+""))), DATEVALUE(K15) - IF(RIGHT(A15,1)=""h"", VALUE(REGEXEXTRACT(A15,""\d+""))/24, IF(RIGHT(A15,1)=""d"", VALUE(REGEXEXTRACT(A15,""\d+"")), IF(RI"&"GHT(A15,1)=""w"", VALUE(REGEXEXTRACT(A15,""\d+""))*7, 0))) ) , ""YYYY-M-D"")"),"2026-2-26") -> 2026-2-26
A16: 4d | B16: HR Data & Analytics Expert (Budapest, HU, 1031) | C16: Budapest, Budapest, Hungary | D16: Onsite | E16: Full Time | F16: Graphisoft | G16: Graphisoft: Develops BIM software solutions for architecture and engineering professionals. | H16: 3+ YOEAnalyze HR data, build dashboards, apply AI, and govern HR data to enable strategic HR decisions. | I16: Power BI, Tableau, HRIS, Statistical software | J16: Job Posting | K16: 46083 | L16: Departments - Data and Analytics, Budapest (Remote, Hybrid, Onsite), No keyword search, 6 months | M16: =IFERROR(__xludf.DUMMYFUNCTION("TEXT( IF(RIGHT(A16,2)=""mo"", EDATE(DATEVALUE(K16), -VALUE(REGEXEXTRACT(A16,""\d+""))), DATEVALUE(K16) - IF(RIGHT(A16,1)=""h"", VALUE(REGEXEXTRACT(A16,""\d+""))/24, IF(RIGHT(A16,1)=""d"", VALUE(REGEXEXTRACT(A16,""\d+"")), IF(RI"&"GHT(A16,1)=""w"", VALUE(REGEXEXTRACT(A16,""\d+""))*7, 0))) ) , ""YYYY-M-D"")"),"2026-2-26") -> 2026-2-26
A17: 4d | B17: Workforce Management Analyst | C17: Budapest, Budapest, Hungary | D17: Hybrid | E17: Full Time | F17: Delivery Hero | G17: Delivery HeroFrankfurt Stock Exchange: DHER: Global platform for online food ordering and delivery services. | H17: 3+ YOE3–4 years in workforce management planning/scheduling; English proficiency; advanced Excel; SQL; Python; strong data analysis skills. | I17: Google Suite, Microsoft Office, Excel, SQL, Python, Erlang-C | J17: Job Posting | K17: 46083 | L17: Departments - Data and Analytics, Budapest (Remote, Hybrid, Onsite), No keyword search, 6 months | M17: =IFERROR(__xludf.DUMMYFUNCTION("TEXT( IF(RIGHT(A17,2)=""mo"", EDATE(DATEVALUE(K17), -VALUE(REGEXEXTRACT(A17,""\d+""))), DATEVALUE(K17) - IF(RIGHT(A17,1)=""h"", VALUE(REGEXEXTRACT(A17,""\d+""))/24, IF(RIGHT(A17,1)=""d"", VALUE(REGEXEXTRACT(A17,""\d+"")), IF(RI"&"GHT(A17,1)=""w"", VALUE(REGEXEXTRACT(A17,""\d+""))*7, 0))) ) , ""YYYY-M-D"")"),"2026-2-26") -> 2026-2-26
A18: 4d | B18: Data Scientist (REF5099W) | C18: Budapest or Debrecen or Pécs or Szeged | D18: Hybrid | E18: Full Time | F18: Deutsche Telekom IT Solutions | G18: Deutsche Telekom IT SolutionsFrankfurt Stock Exchange: DTE: Provides integrated IT and telecommunications services to corporate clients. | H18: Bachelor’s degree in IT/related fields; data science/ML/analytics experience; NoSQL; REST/JSON; Python; GitLab CI/CD; Docker/Kubernetes; Elastic/OpenSearch; Kafka; Linux; English. | I18: NoSQL, REST-API, JSON, Python, GitLab CI/CD, Docker, Kubernetes, Elasticsearch/OpenSearch, Kafka, Linux | J18: Job Posting | K18: 46083 | L18: Departments - Data and Analytics, Budapest (Remote, Hybrid, Onsite), No keyword search, 6 months | M18: =IFERROR(__xludf.DUMMYFUNCTION("TEXT( IF(RIGHT(A18,2)=""mo"", EDATE(DATEVALUE(K18), -VALUE(REGEXEXTRACT(A18,""\d+""))), DATEVALUE(K18) - IF(RIGHT(A18,1)=""h"", VALUE(REGEXEXTRACT(A18,""\d+""))/24, IF(RIGHT(A18,1)=""d"", VALUE(REGEXEXTRACT(A18,""\d+"")), IF(RI"&"GHT(A18,1)=""w"", VALUE(REGEXEXTRACT(A18,""\d+""))*7, 0))) ) , ""YYYY-M-D"")"),"2026-2-26") -> 2026-2-26
A19: 4d | B19: Product Analyst, Donor Portal | C19: Georgia or Europe | D19: Remote | E19: Full Time | F19: Fundraise Up | G19: Fundraise Up: AI-powered fundraising platform for nonprofit organizations. | H19: 5+ YOE5+ years as Data/Product Analyst; strong statistics; advanced SQL; Python (NumPy, Pandas, Matplotlib, Scikit-learn); BI tools (Tableau, Power BI, Metabase); strong English; proactive, detail-oriented. | I19: Python, SQL, Tableau, Power BI, Metabase, Grafana, Airflow, Git, ClickHouse, MongoDB, PostgreSQL | J19: Job Posting | K19: 46083 | L19: Departments - Data and Analytics, Budapest (Remote, Hybrid, Onsite), No keyword search, 6 months | M19: =IFERROR(__xludf.DUMMYFUNCTION("TEXT( IF(RIGHT(A19,2)=""mo"", EDATE(DATEVALUE(K19), -VALUE(REGEXEXTRACT(A19,""\d+""))), DATEVALUE(K19) - IF(RIGHT(A19,1)=""h"", VALUE(REGEXEXTRACT(A19,""\d+""))/24, IF(RIGHT(A19,1)=""d"", VALUE(REGEXEXTRACT(A19,""\d+"")), IF(RI"&"GHT(A19,1)=""w"", VALUE(REGEXEXTRACT(A19,""\d+""))*7, 0))) ) , ""YYYY-M-D"")"),"2026-2-26") -> 2026-2-26
A20: 4d | B20: Data Analytics | C20: Europe | D20: Remote | E20: Full Time | F20: Miratech | G20: Miratech: Global IT consulting firm providing digital engineering and CX services. | H20: 3+ YOE3+ years in data analysis; strong SQL, Excel; Tableau; experience with IVR or contact center data; good communication. | I20: SQL, Excel, Tableau | J20: Job Posting | K20: 46083 | L20: Departments - Data and Analytics, Budapest (Remote, Hybrid, Onsite), No keyword search, 6 months | M20: =IFERROR(__xludf.DUMMYFUNCTION("TEXT( IF(RIGHT(A20,2)=""mo"", EDATE(DATEVALUE(K20), -VALUE(REGEXEXTRACT(A20,""\d+""))), DATEVALUE(K20) - IF(RIGHT(A20,1)=""h"", VALUE(REGEXEXTRACT(A20,""\d+""))/24, IF(RIGHT(A20,1)=""d"", VALUE(REGEXEXTRACT(A20,""\d+"")), IF(RI"&"GHT(A20,1)=""w"", VALUE(REGEXEXTRACT(A20,""\d+""))*7, 0))) ) , ""YYYY-M-D"")"),"2026-2-26") -> 2026-2-26
A21: 5d | B21: Data Governance Lead | C21: Budapest, Budapest, Hungary | D21: Hybrid | E21: Full Time | F21: Sanofi | G21: SanofiNASDAQ: SNY: Develops and manufactures pharmaceuticals and vaccines for global patients. | H21: Lead global data governance, ensure data quality and compliance; manage data stewards; implement governance strategies. | I21: MDM, CI/CD, Data governance, Agile | J21: Job Posting | K21: 46083 | L21: Departments - Data and Analytics, Budapest (Remote, Hybrid, Onsite), No keyword search, 6 months | M21: =IFERROR(__xludf.DUMMYFUNCTION("TEXT( IF(RIGHT(A21,2)=""mo"", EDATE(DATEVALUE(K21), -VALUE(REGEXEXTRACT(A21,""\d+""))), DATEVALUE(K21) - IF(RIGHT(A21,1)=""h"", VALUE(REGEXEXTRACT(A21,""\d+""))/24, IF(RIGHT(A21,1)=""d"", VALUE(REGEXEXTRACT(A21,""\d+"")), IF(RI"&"GHT(A21,1)=""w"", VALUE(REGEXEXTRACT(A21,""\d+""))*7, 0))) ) , ""YYYY-M-D"")"),"2026-2-25") -> 2026-2-25
A22: 5d | B22: Lead Data Engineer | C22: Budapest, Budapest, Hungary | D22: Hybrid | E22: Full Time | F22: Morgan Stanley | G22: Morgan StanleyNYSE: MS: Provides investment banking, wealth management, and financial services. | H22: 6+ YOELead data engineer with 6+ years in data engineering, data architecture, SQL, ETL, cloud platforms (Snowflake), GenAI/AI/ML, and strong leadership. | I22: Snowflake, SQL, ETL, GenAI, LLMs, CI/CD, AI/ML tools | J22: Job Posting | K22: 46083 | L22: Departments - Data and Analytics, Budapest (Remote, Hybrid, Onsite), No keyword search, 6 months | M22: =IFERROR(__xludf.DUMMYFUNCTION("TEXT( IF(RIGHT(A22,2)=""mo"", EDATE(DATEVALUE(K22), -VALUE(REGEXEXTRACT(A22,""\d+""))), DATEVALUE(K22) - IF(RIGHT(A22,1)=""h"", VALUE(REGEXEXTRACT(A22,""\d+""))/24, IF(RIGHT(A22,1)=""d"", VALUE(REGEXEXTRACT(A22,""\d+"")), IF(RI"&"GHT(A22,1)=""w"", VALUE(REGEXEXTRACT(A22,""\d+""))*7, 0))) ) , ""YYYY-M-D"")"),"2026-2-25") -> 2026-2-25
A23: 5d | B23: AI Training Specialist | C23: North America or Europe or Asia | D23: Remote | E23: Contract | F23: Prolific | G23: Prolific: Connecting researchers with vetted participants for high-quality data collection. | H23: 0+ YOEExperience as AI trainer or similar; ability to complete paid tasks with focus for up to an hour; reliable internet; computer access; willingness to self-declare earnings; PayPal familiar; willing to take verification test. | I23: General AI Training, Image and Video Annotation, Trust and Safety, Evaluations, Red Teaming, Quality Analytics | J23: Job Posting | K23: 46083 | L23: Departments - Data and Analytics, Budapest (Remote, Hybrid, Onsite), No keyword search, 6 months | M23: =IFERROR(__xludf.DUMMYFUNCTION("TEXT( IF(RIGHT(A23,2)=""mo"", EDATE(DATEVALUE(K23), -VALUE(REGEXEXTRACT(A23,""\d+""))), DATEVALUE(K23) - IF(RIGHT(A23,1)=""h"", VALUE(REGEXEXTRACT(A23,""\d+""))/24, IF(RIGHT(A23,1)=""d"", VALUE(REGEXEXTRACT(A23,""\d+"")), IF(RI"&"GHT(A23,1)=""w"", VALUE(REGEXEXTRACT(A23,""\d+""))*7, 0))) ) , ""YYYY-M-D"")"),"2026-2-25") -> 2026-2-25
A24: 5d | B24: Product Analyst | C24: Europe | D24: Remote | E24: Contract | F24: Scentbird | G24: Scentbird: Monthly subscription service for sampling designer perfumes and colognes. | H24: Experience in product analytics and data-driven decision making. | I24: Not available | J24: Job Posting | K24: 46083 | L24: Departments - Data and Analytics, Budapest (Remote, Hybrid, Onsite), No keyword search, 6 months | M24: =IFERROR(__xludf.DUMMYFUNCTION("TEXT( IF(RIGHT(A24,2)=""mo"", EDATE(DATEVALUE(K24), -VALUE(REGEXEXTRACT(A24,""\d+""))), DATEVALUE(K24) - IF(RIGHT(A24,1)=""h"", VALUE(REGEXEXTRACT(A24,""\d+""))/24, IF(RIGHT(A24,1)=""d"", VALUE(REGEXEXTRACT(A24,""\d+"")), IF(RI"&"GHT(A24,1)=""w"", VALUE(REGEXEXTRACT(A24,""\d+""))*7, 0))) ) , ""YYYY-M-D"")"),"2026-2-25") -> 2026-2-25
A25: 6d | B25: Master Data Management Associate | C25: Budapest, Budapest, Hungary | D25: Onsite | E25: Full Time | F25: Tesco | G25: TescoLondon Stock Exchange: TSCO: Operates a global network of grocery and retail stores. | H25: 1+ YOEHigh school diploma; upper-intermediate English; Hungarian; 1-3 years relevant experience; proactivity; analytical skills; accuracy and attention to detail; effective communication. | I25: Oracle | J25: Job Posting | K25: 46083 | L25: Departments - Data and Analytics, Budapest (Remote, Hybrid, Onsite), No keyword search, 6 months | M25: =IFERROR(__xludf.DUMMYFUNCTION("TEXT( IF(RIGHT(A25,2)=""mo"", EDATE(DATEVALUE(K25), -VALUE(REGEXEXTRACT(A25,""\d+""))), DATEVALUE(K25) - IF(RIGHT(A25,1)=""h"", VALUE(REGEXEXTRACT(A25,""\d+""))/24, IF(RIGHT(A25,1)=""d"", VALUE(REGEXEXTRACT(A25,""\d+"")), IF(RI"&"GHT(A25,1)=""w"", VALUE(REGEXEXTRACT(A25,""\d+""))*7, 0))) ) , ""YYYY-M-D"")"),"2026-2-24") -> 2026-2-24
A26: 6d | B26: Data & Analytics Product Manager - Supply | C26: Budapest or Bangalore | D26: Hybrid | E26: Full Time | F26: Diageo | G26: DiageoLondon Stock Exchange: DGE: Produces and distributes premium alcoholic beverages worldwide. | H26: 4+ YOE2+ Mgmt8+ years in data/analytics; Master’s degree; 4+ years in enterprise data analytics; 2+ years leadership; expertise in predictive modelling, segmentation, ROI measurement; 2+ years in B2B product/program management. | I26: SQL, Python, R, Tableau, Power BI, Excel, ETL, Cloud data platforms | J26: Job Posting | K26: 46083 | L26: Departments - Data and Analytics, Budapest (Remote, Hybrid, Onsite), No keyword search, 6 months | M26: =IFERROR(__xludf.DUMMYFUNCTION("TEXT( IF(RIGHT(A26,2)=""mo"", EDATE(DATEVALUE(K26), -VALUE(REGEXEXTRACT(A26,""\d+""))), DATEVALUE(K26) - IF(RIGHT(A26,1)=""h"", VALUE(REGEXEXTRACT(A26,""\d+""))/24, IF(RIGHT(A26,1)=""d"", VALUE(REGEXEXTRACT(A26,""\d+"")), IF(RI"&"GHT(A26,1)=""w"", VALUE(REGEXEXTRACT(A26,""\d+""))*7, 0))) ) , ""YYYY-M-D"")"),"2026-2-24") -> 2026-2-24
A27: 6d | B27: Operációtámogatási és adatgazdagítási specialista | C27: Budapest, Budapest, Hungary | D27: Hybrid | E27: Full Time | F27: Intrum | G27: IntrumNasdaq Stockholm: INTRUM: Provides credit management and debt collection services to businesses. | H27: 1+ YOESecondary education; 1-2 years experience; precise, deadline-driven; proficient in Excel; team player; problem solving; willing to learn. Power BI and English a plus. | I27: Excel, Power BI | J27: Job Posting | K27: 46083 | L27: Departments - Data and Analytics, Budapest (Remote, Hybrid, Onsite), No keyword search, 6 months | M27: =IFERROR(__xludf.DUMMYFUNCTION("TEXT( IF(RIGHT(A27,2)=""mo"", EDATE(DATEVALUE(K27), -VALUE(REGEXEXTRACT(A27,""\d+""))), DATEVALUE(K27) - IF(RIGHT(A27,1)=""h"", VALUE(REGEXEXTRACT(A27,""\d+""))/24, IF(RIGHT(A27,1)=""d"", VALUE(REGEXEXTRACT(A27,""\d+"")), IF(RI"&"GHT(A27,1)=""w"", VALUE(REGEXEXTRACT(A27,""\d+""))*7, 0))) ) , ""YYYY-M-D"")"),"2026-2-24") -> 2026-2-24
A28: 6d | B28: R0000038368 Manager, Centralized Data & Sample Management - Poland / Spain / Hungary - FSP | C28: Madrid or Poland or Budapest | D28: Remote | E28: Full Time | F28: Parexel | G28: Parexel: Provides clinical trial management and drug development consulting services. | H28: 5+ YOEBachelor’s degree; 5+ years in Clinical Data Management or sample management; knowledge of third-party data; strong project management; communication skills; ability to work with globally distributed teams; willingness to travel. | I28: Electronic Data Capture (EDC), Rave, InForm, data management systems | J28: Job Posting | K28: 46083 | L28: Departments - Data and Analytics, Budapest (Remote, Hybrid, Onsite), No keyword search, 6 months | M28: =IFERROR(__xludf.DUMMYFUNCTION("TEXT( IF(RIGHT(A28,2)=""mo"", EDATE(DATEVALUE(K28), -VALUE(REGEXEXTRACT(A28,""\d+""))), DATEVALUE(K28) - IF(RIGHT(A28,1)=""h"", VALUE(REGEXEXTRACT(A28,""\d+""))/24, IF(RIGHT(A28,1)=""d"", VALUE(REGEXEXTRACT(A28,""\d+"")), IF(RI"&"GHT(A28,1)=""w"", VALUE(REGEXEXTRACT(A28,""\d+""))*7, 0))) ) , ""YYYY-M-D"")"),"2026-2-24") -> 2026-2-24
A29: 6d | B29: Erőmű adatelemző szakértő (Budapest, HU) | C29: Budapest or Debrecen | D29: Onsite | E29: Full Time | F29: E.ON | G29: E.ONXetra: EOAN: Operates energy networks and provides consumer energy solutions. | H29: 5+ YOEStrong analytical skills with SQL, Power BI, Python; experience in data warehousing, automation, and IT systems in energy sector. | I29: Power BI, SQL, Python, Excel Macros, Power Apps, R, RStudio, Databricks, MS Power Platform | J29: Job Posting | K29: 46083 | L29: Departments - Data and Analytics, Budapest (Remote, Hybrid, Onsite), No keyword search, 6 months | M29: =IFERROR(__xludf.DUMMYFUNCTION("TEXT( IF(RIGHT(A29,2)=""mo"", EDATE(DATEVALUE(K29), -VALUE(REGEXEXTRACT(A29,""\d+""))), DATEVALUE(K29) - IF(RIGHT(A29,1)=""h"", VALUE(REGEXEXTRACT(A29,""\d+""))/24, IF(RIGHT(A29,1)=""d"", VALUE(REGEXEXTRACT(A29,""\d+"")), IF(RI"&"GHT(A29,1)=""w"", VALUE(REGEXEXTRACT(A29,""\d+""))*7, 0))) ) , ""YYYY-M-D"")"),"2026-2-24") -> 2026-2-24
A30: 1w | B30: Enterprise Data Office - Production Support Senior Analyst | C30: Budapest, Budapest, Hungary | D30: Hybrid | E30: Full Time | F30: Citi | G30: CitiNYSE: C: Global financial institution providing retail, corporate, and investment banking services. | H30: 4+ YOE4-6 years in production support; knowledge of ServiceNow, JIRA, Confluence; MS Office; SharePoint a plus; strong incident/problem management; English fluency. | I30: ServiceNow, Atlassian JIRA, Confluence, Agile, Microsoft Word, Microsoft Excel, Microsoft PowerPoint, MS Visio, SharePoint | J30: Job Posting | K30: 46083 | L30: Departments - Data and Analytics, Budapest (Remote, Hybrid, Onsite), No keyword search, 6 months | M30: =IFERROR(__xludf.DUMMYFUNCTION("TEXT( IF(RIGHT(A30,2)=""mo"", EDATE(DATEVALUE(K30), -VALUE(REGEXEXTRACT(A30,""\d+""))), DATEVALUE(K30) - IF(RIGHT(A30,1)=""h"", VALUE(REGEXEXTRACT(A30,""\d+""))/24, IF(RIGHT(A30,1)=""d"", VALUE(REGEXEXTRACT(A30,""\d+"")), IF(RI"&"GHT(A30,1)=""w"", VALUE(REGEXEXTRACT(A30,""\d+""))*7, 0))) ) , ""YYYY-M-D"")"),"2026-2-23") -> 2026-2-23
A31: 1w | B31: AI Data Specialist - Hungarian | C31: Budapest, Budapest, Hungary | D31: Remote | E31: Contract, Part Time | F31: RWS | G31: RWSLondon Stock Exchange: RWS: Provides global translation, intellectual property, and AI language solutions. | H31: Freelance, part-time role for Hungarian language data work; remote; tasks include data collection, evaluation, annotation; need Hungarian native level and English proficiency; flexible schedule. | I31: Data annotation, Labeling | J31: Job Posting | K31: 46083 | L31: Departments - Data and Analytics, Budapest (Remote, Hybrid, Onsite), No keyword search, 6 months | M31: =IFERROR(__xludf.DUMMYFUNCTION("TEXT( IF(RIGHT(A31,2)=""mo"", EDATE(DATEVALUE(K31), -VALUE(REGEXEXTRACT(A31,""\d+""))), DATEVALUE(K31) - IF(RIGHT(A31,1)=""h"", VALUE(REGEXEXTRACT(A31,""\d+""))/24, IF(RIGHT(A31,1)=""d"", VALUE(REGEXEXTRACT(A31,""\d+"")), IF(RI"&"GHT(A31,1)=""w"", VALUE(REGEXEXTRACT(A31,""\d+""))*7, 0))) ) , ""YYYY-M-D"")"),"2026-2-23") -> 2026-2-23
A32: 1w | B32: SEO Expert | C32: Budapest, Budapest, Hungary | D32: Remote | E32: Full Time | F32: Hustler Marketing | G32: Hustler Marketing: Provides data-driven email and SMS marketing for eCommerce brands. | H32: 4+ YOE5 years+ SEO for ecommerce; client-facing; agency/freelance background; strong technical SEO; experience with Shopify/WooCommerce/Magento; English communication; remote work. | I32: Ahrefs, SEMrush, Screaming Frog, Google Analytics, Google Search Console, Shopify, WooCommerce, Magento, BigCommerce | J32: Job Posting | K32: 46083 | L32: Departments - Data and Analytics, Budapest (Remote, Hybrid, Onsite), No keyword search, 6 months | M32: =IFERROR(__xludf.DUMMYFUNCTION("TEXT( IF(RIGHT(A32,2)=""mo"", EDATE(DATEVALUE(K32), -VALUE(REGEXEXTRACT(A32,""\d+""))), DATEVALUE(K32) - IF(RIGHT(A32,1)=""h"", VALUE(REGEXEXTRACT(A32,""\d+""))/24, IF(RIGHT(A32,1)=""d"", VALUE(REGEXEXTRACT(A32,""\d+"")), IF(RI"&"GHT(A32,1)=""w"", VALUE(REGEXEXTRACT(A32,""\d+""))*7, 0))) ) , ""YYYY-M-D"")"),"2026-2-23") -> 2026-2-23
A33: 1w | B33: Senior Data Management Expert | C33: Budapest, Budapest, Hungary | D33: Hybrid | E33: Full Time | F33: YouGov | G33: YouGovLondon Stock Exchange: YOU: International online market research and data analytics technology. | H33: Advanced Excel with macros; strong database management; fluent English and Hungarian; UNIX basics; SPSS; MS Access; Budapest-based hybrid role. | I33: Microsoft Excel, UNIX, SPSS, MS Access | J33: Job Posting | K33: 46083 | L33: Departments - Data and Analytics, Budapest (Remote, Hybrid, Onsite), No keyword search, 6 months | M33: =IFERROR(__xludf.DUMMYFUNCTION("TEXT( IF(RIGHT(A33,2)=""mo"", EDATE(DATEVALUE(K33), -VALUE(REGEXEXTRACT(A33,""\d+""))), DATEVALUE(K33) - IF(RIGHT(A33,1)=""h"", VALUE(REGEXEXTRACT(A33,""\d+""))/24, IF(RIGHT(A33,1)=""d"", VALUE(REGEXEXTRACT(A33,""\d+"")), IF(RI"&"GHT(A33,1)=""w"", VALUE(REGEXEXTRACT(A33,""\d+""))*7, 0))) ) , ""YYYY-M-D"")"),"2026-2-23") -> 2026-2-23
A34: 1w | B34: Senior Data Management Expert | C34: Budapest, Budapest, Hungary | D34: Hybrid | E34: Full Time | F34: YouGov | G34: YouGovLondon Stock Exchange: YOU: Provides global consumer data and market research insights. | H34: Advanced Excel, strong database management, English and Hungarian, UNIX, SPSS, MS Access; hybrid Budapest; 3 days in office. | I34: Microsoft Excel, UNIX, SPSS, MS Access, Macros | J34: Job Posting | K34: 46083 | L34: Departments - Data and Analytics, Budapest (Remote, Hybrid, Onsite), No keyword search, 6 months | M34: =IFERROR(__xludf.DUMMYFUNCTION("TEXT( IF(RIGHT(A34,2)=""mo"", EDATE(DATEVALUE(K34), -VALUE(REGEXEXTRACT(A34,""\d+""))), DATEVALUE(K34) - IF(RIGHT(A34,1)=""h"", VALUE(REGEXEXTRACT(A34,""\d+""))/24, IF(RIGHT(A34,1)=""d"", VALUE(REGEXEXTRACT(A34,""\d+"")), IF(RI"&"GHT(A34,1)=""w"", VALUE(REGEXEXTRACT(A34,""\d+""))*7, 0))) ) , ""YYYY-M-D"")"),"2026-2-23") -> 2026-2-23
A35: 1w | B35: Downstream Business Analyst Expert | C35: Budapest, Budapest, Hungary | D35: Onsite | E35: Full Time | F35: MOL Group | G35: MOL GroupBudapest Stock Exchange: MOL: Integrated international providing oil and gas products. | H35: 2+ YOEUniversity/college degree in finance/economics; 0-2 years’ experience; highly proficient in Excel; fluent English; strong financial/performance analysis; problem solving; structured thinking; collaborative. | I35: Microsoft Excel | J35: Job Posting | K35: 46083 | L35: Departments - Data and Analytics, Budapest (Remote, Hybrid, Onsite), No keyword search, 6 months | M35: =IFERROR(__xludf.DUMMYFUNCTION("TEXT( IF(RIGHT(A35,2)=""mo"", EDATE(DATEVALUE(K35), -VALUE(REGEXEXTRACT(A35,""\d+""))), DATEVALUE(K35) - IF(RIGHT(A35,1)=""h"", VALUE(REGEXEXTRACT(A35,""\d+""))/24, IF(RIGHT(A35,1)=""d"", VALUE(REGEXEXTRACT(A35,""\d+"")), IF(RI"&"GHT(A35,1)=""w"", VALUE(REGEXEXTRACT(A35,""\d+""))*7, 0))) ) , ""YYYY-M-D"")"),"2026-2-23") -> 2026-2-23
A36: 1w | B36: Finance Systems Manager | C36: Budapest, Budapest, Hungary | D36: Onsite | E36: Full Time | F36: Danaher | G36: DanaherNYSE: DHR: Global innovator in diagnostics, life sciences, and biotechnology solutions. | H36: BS/MS in Business, Finance, IT, Project or similar; strong QlikSense; proven ability to lead global cross-functional teams; analytical, problem-solving, and communication skills. | I36: QlikSense | J36: Job Posting | K36: 46083 | L36: Departments - Data and Analytics, Budapest (Remote, Hybrid, Onsite), No keyword search, 6 months | M36: =IFERROR(__xludf.DUMMYFUNCTION("TEXT( IF(RIGHT(A36,2)=""mo"", EDATE(DATEVALUE(K36), -VALUE(REGEXEXTRACT(A36,""\d+""))), DATEVALUE(K36) - IF(RIGHT(A36,1)=""h"", VALUE(REGEXEXTRACT(A36,""\d+""))/24, IF(RIGHT(A36,1)=""d"", VALUE(REGEXEXTRACT(A36,""\d+"")), IF(RI"&"GHT(A36,1)=""w"", VALUE(REGEXEXTRACT(A36,""\d+""))*7, 0))) ) , ""YYYY-M-D"")"),"2026-2-23") -> 2026-2-23
A37: 1w | B37: Software Engineer, Data Platform | C37: Europe | D37: Remote | E37: Full Time | F37: Pagos | G37: Pagos: Software platform that optimizes business payment infrastructure and data. | H37: 8+ YOE8+ years of software engineering with a focus on data engineering; strong backend, APIs, and data pipelines; experience with cloud platforms and data technologies. | I37: SQL, REST, gRPC, AWS, GCP, Azure, Redshift, Clickhouse, Trino, StarRocks, Apache Iceberg, Postgres, S3, EMR, Glue, Kinesis, Athena, DBT | J37: Job Posting | K37: 46083 | L37: Departments - Data and Analytics, Budapest (Remote, Hybrid, Onsite), No keyword search, 6 months | M37: =IFERROR(__xludf.DUMMYFUNCTION("TEXT( IF(RIGHT(A37,2)=""mo"", EDATE(DATEVALUE(K37), -VALUE(REGEXEXTRACT(A37,""\d+""))), DATEVALUE(K37) - IF(RIGHT(A37,1)=""h"", VALUE(REGEXEXTRACT(A37,""\d+""))/24, IF(RIGHT(A37,1)=""d"", VALUE(REGEXEXTRACT(A37,""\d+"")), IF(RI"&"GHT(A37,1)=""w"", VALUE(REGEXEXTRACT(A37,""\d+""))*7, 0))) ) , ""YYYY-M-D"")"),"2026-2-23") -> 2026-2-23
A38: 1w | B38: Data engineer trainee | C38: Budapest, Budapest, Hungary | D38: Hybrid | E38: Internship | F38: Bosch | G38: Bosch: Global provider of technology for mobility and smart homes. | H38: Internship student with programming knowledge in Python and SQL; basic data science understanding; 20 hours/week minimum; Hungarian language; Git familiarity; English at least intermediate. | I38: Python, SQL, Pandas, Numpy, Scipy, Matplotlib, TensorFlow, Git | J38: Job Posting | K38: 46083 | L38: Departments - Data and Analytics, Budapest (Remote, Hybrid, Onsite), No keyword search, 6 months | M38: =IFERROR(__xludf.DUMMYFUNCTION("TEXT( IF(RIGHT(A38,2)=""mo"", EDATE(DATEVALUE(K38), -VALUE(REGEXEXTRACT(A38,""\d+""))), DATEVALUE(K38) - IF(RIGHT(A38,1)=""h"", VALUE(REGEXEXTRACT(A38,""\d+""))/24, IF(RIGHT(A38,1)=""d"", VALUE(REGEXEXTRACT(A38,""\d+"")), IF(RI"&"GHT(A38,1)=""w"", VALUE(REGEXEXTRACT(A38,""\d+""))*7, 0))) ) , ""YYYY-M-D"")"),"2026-2-23") -> 2026-2-23
A39: 1w | B39: Junior Operations Performance Manager (Budapest, HU, H-1095) | C39: Budapest, Budapest, Hungary | D39: Onsite | E39: Full Time | F39: Wizz Air | G39: Wizz AirLondon Stock Exchange: WIZZ: Ultra-low-cost airline offering point-to-point passenger flights. | H39: 1+ YOE1-3+ years in data analysis; experience with data visualization; English fluency. | I39: MS Excel, Power Pivot, Power Query, Power BI, SQL, DAX, Data Visualization | J39: Job Posting | K39: 46083 | L39: Departments - Data and Analytics, Budapest (Remote, Hybrid, Onsite), No keyword search, 6 months | M39: =IFERROR(__xludf.DUMMYFUNCTION("TEXT( IF(RIGHT(A39,2)=""mo"", EDATE(DATEVALUE(K39), -VALUE(REGEXEXTRACT(A39,""\d+""))), DATEVALUE(K39) - IF(RIGHT(A39,1)=""h"", VALUE(REGEXEXTRACT(A39,""\d+""))/24, IF(RIGHT(A39,1)=""d"", VALUE(REGEXEXTRACT(A39,""\d+"")), IF(RI"&"GHT(A39,1)=""w"", VALUE(REGEXEXTRACT(A39,""\d+""))*7, 0))) ) , ""YYYY-M-D"")"),"2026-2-23") -> 2026-2-23
A40: 1w | B40: Senior Data Platform Engineer | C40: Budapest, Budapest, Hungary | D40: Onsite | E40: Full Time | F40: GSCF | G40: GSCF: Provides technology-enabled working capital and supply chain finance solutions. | H40: 5+ YOE5+ years SQL, 3+ years data warehouse design/ops, 3+ years cloud (AWS/Azure/GCP), experience with Airflow/Dagster, 5+ years programming (Python/Java/Scala), experience with Snowflake/Redshift/Databricks/BigQuery | I40: SQL, Airflow, Dagster, Python, Java, Scala, Snowflake, Redshift, Databricks, BigQuery, dbt, Terraform, Power BI, Tableau, Power Query, DAX | J40: Job Posting | K40: 46083 | L40: Departments - Data and Analytics, Budapest (Remote, Hybrid, Onsite), No keyword search, 6 months | M40: =IFERROR(__xludf.DUMMYFUNCTION("TEXT( IF(RIGHT(A40,2)=""mo"", EDATE(DATEVALUE(K40), -VALUE(REGEXEXTRACT(A40,""\d+""))), DATEVALUE(K40) - IF(RIGHT(A40,1)=""h"", VALUE(REGEXEXTRACT(A40,""\d+""))/24, IF(RIGHT(A40,1)=""d"", VALUE(REGEXEXTRACT(A40,""\d+"")), IF(RI"&"GHT(A40,1)=""w"", VALUE(REGEXEXTRACT(A40,""\d+""))*7, 0))) ) , ""YYYY-M-D"")"),"2026-2-23") -> 2026-2-23
...

Sheet HiringCafe_Job_Clean
A1: Column column | B1: Data column | C1: Quality check
A5: Posted Time
A6: Role
A7: Area
A8: Work Type
A9: Contract Type
A10: Company
A11: Company & Description
A12: Requirements Summary
A13: Technical Tools mentioned
A14: Job Posting | C14: =IF(A14=B14, "Entry is True", "Check this Entry") -> Check this Entry

Sheet HiringCafe_Job_Format
A1: Posted Time | B1: Role | C1: Area | D1: Work Type | E1: Contract Type | F1: Company | G1: Company & Description | H1: Requirements Summary | I1: Technical Tools mentioned | J1: Job Posting | K1: Added Date | L1: Type of Search
A2: {=IFERROR(INDEX(HiringCafe_Job_Clean!$B:$B, SMALL(IF(HiringCafe_Job_Clean!$A$1:$A$5027="Posted Time", ROW(HiringCafe_Job_Clean!$A$1:$A$5027)), ROW()-1)), "")} | B2: {=IFERROR(INDEX(HiringCafe_Job_Clean!$B:$B, SMALL(IF(HiringCafe_Job_Clean!$A$1:$A$5027="Role", ROW(HiringCafe_Job_Clean!$A$1:$A$5027)), ROW()-1)), "")} | C2: {=IFERROR(INDEX(HiringCafe_Job_Clean!$B:$B, SMALL(IF(HiringCafe_Job_Clean!$A$1:$A$5027="Area", ROW(HiringCafe_Job_Clean!$A$1:$A$5027)), ROW()-1)), "")} | D2: {=IFERROR(INDEX(HiringCafe_Job_Clean!$B:$B, SMALL(IF(HiringCafe_Job_Clean!$A$1:$A$5027="Work Type", ROW(HiringCafe_Job_Clean!$A$1:$A$5027)), ROW()-1)), "")} | E2: {=IFERROR(INDEX(HiringCafe_Job_Clean!$B:$B, SMALL(IF(HiringCafe_Job_Clean!$A$1:$A$5027="Contract Type", ROW(HiringCafe_Job_Clean!$A$1:$A$5027)), ROW()-1)), "")} | F2: {=IFERROR(INDEX(HiringCafe_Job_Clean!$B:$B, SMALL(IF(HiringCafe_Job_Clean!$A$1:$A$5027="Company", ROW(HiringCafe_Job_Clean!$A$1:$A$5027)), ROW()-1)), "")} | G2: {=IFERROR(INDEX(HiringCafe_Job_Clean!$B:$B, SMALL(IF(HiringCafe_Job_Clean!$A$1:$A$5027="Company & Description", ROW(HiringCafe_Job_Clean!$A$1:$A$5027)), ROW()-1)), "")} | H2: {=IFERROR(INDEX(HiringCafe_Job_Clean!$B:$B, SMALL(IF(HiringCafe_Job_Clean!$A$1:$A$5027="Requirements Summary", ROW(HiringCafe_Job_Clean!$A$1:$A$5027)), ROW()-1)), "")} | I2: {=IFERROR(INDEX(HiringCafe_Job_Clean!$B:$B, SMALL(IF(HiringCafe_Job_Clean!$A$1:$A$5027="Technical Tools mentioned", ROW(HiringCafe_Job_Clean!$A$1:$A$5027)), ROW()-1)), "")} | J2: {=IFERROR(INDEX(HiringCafe_Job_Clean!$B:$B, SMALL(IF(HiringCafe_Job_Clean!$A$1:$A$5027="Job Posting", ROW(HiringCafe_Job_Clean!$A$1:$A$5027)), ROW()-1)), "")}
K201: - | L201: -
